# Persistent Storage of Data

Exception handling is an important aspect of Java programming. Exceptions are unexpected or exceptional events that occur during the execution of a program. These events can be caused by a variety of factors, such as invalid user input, network errors, or unexpected conditions in the environment.

In Java, exception handling is done using try-catch blocks. The code that might throw an exception is placed inside a try block, and any potential exceptions are caught and handled in a catch block. Here is an example:

```
try {
    // code that might throw an exception
    int result = divideNumbers(10, 0);
    System.out.println("Result: " + result);
} catch (ArithmeticException e) {
    // exception handler
    System.out.println("Error: division by zero");
}

```
In this example, the divideNumbers() method might throw an ArithmeticException if the second argument (the divisor) is zero. The method call is placed inside a try block, and any exceptions that are thrown will be caught and handled by the catch block.

Java provides several types of built-in exceptions, such as ArithmeticException, NullPointerException, and IOException. You can also create your own custom exceptions by extending the Exception class.

It's important to handle exceptions appropriately in your code to prevent unexpected behavior or crashes. In addition to catching exceptions, you can also use the finally block to specify code that should be executed regardless of whether an exception is thrown or not. Here is an example:

```
try {
    // code that might throw an exception
    someMethodThatMightThrowAnException();
} catch (SomeException e) {
    // exception handler
    System.out.println("Error: " + e.getMessage());
} finally {
    // code that should be executed regardless of whether an exception is thrown
    cleanUpResources();
}

```

In this example, the cleanUpResources() method will be executed even if an exception is thrown and caught. This is useful for releasing resources or closing connections that were opened in the try block.